2024-03-31 12:55:46,559 INFO    StreamThr :3789203 [internal.py:wandb_internal():86] W&B internal server running at pid: 3789203, started at: 2024-03-31 12:55:46.558951
2024-03-31 12:55:46,561 DEBUG   HandlerThread:3789203 [handler.py:handle_request():146] handle_request: status
2024-03-31 12:55:46,561 INFO    WriterThread:3789203 [datastore.py:open_for_write():87] open: /cpfs01/user/chenqin.p/dyh/MOELoRA-peft/wandb/run-20240331_125546-1viczsce/run-1viczsce.wandb
2024-03-31 12:55:46,563 DEBUG   SenderThread:3789203 [sender.py:send():382] send: header
2024-03-31 12:55:46,563 DEBUG   SenderThread:3789203 [sender.py:send():382] send: run
2024-03-31 12:55:51,564 DEBUG   HandlerThread:3789203 [handler.py:handle_request():146] handle_request: keepalive
2024-03-31 12:55:56,565 DEBUG   HandlerThread:3789203 [handler.py:handle_request():146] handle_request: keepalive
2024-03-31 12:56:01,566 DEBUG   HandlerThread:3789203 [handler.py:handle_request():146] handle_request: keepalive
2024-03-31 12:56:06,567 DEBUG   HandlerThread:3789203 [handler.py:handle_request():146] handle_request: keepalive
2024-03-31 12:56:11,568 DEBUG   HandlerThread:3789203 [handler.py:handle_request():146] handle_request: keepalive
2024-03-31 12:56:16,569 DEBUG   HandlerThread:3789203 [handler.py:handle_request():146] handle_request: keepalive
2024-03-31 12:56:21,570 DEBUG   HandlerThread:3789203 [handler.py:handle_request():146] handle_request: keepalive
2024-03-31 12:56:26,571 DEBUG   HandlerThread:3789203 [handler.py:handle_request():146] handle_request: keepalive
2024-03-31 12:56:31,572 DEBUG   HandlerThread:3789203 [handler.py:handle_request():146] handle_request: keepalive
2024-03-31 12:56:36,572 DEBUG   HandlerThread:3789203 [handler.py:handle_request():146] handle_request: keepalive
2024-03-31 12:56:41,217 INFO    SenderThread:3789203 [retry.py:__call__():172] Retry attempt failed:
Traceback (most recent call last):
  File "/cpfs01/user/chenqin.p/anaconda3/envs/moe/lib/python3.10/site-packages/urllib3/connectionpool.py", line 715, in urlopen
    httplib_response = self._make_request(
  File "/cpfs01/user/chenqin.p/anaconda3/envs/moe/lib/python3.10/site-packages/urllib3/connectionpool.py", line 467, in _make_request
    six.raise_from(e, None)
  File "<string>", line 3, in raise_from
  File "/cpfs01/user/chenqin.p/anaconda3/envs/moe/lib/python3.10/site-packages/urllib3/connectionpool.py", line 462, in _make_request
    httplib_response = conn.getresponse()
  File "/cpfs01/user/chenqin.p/anaconda3/envs/moe/lib/python3.10/http/client.py", line 1375, in getresponse
    response.begin()
  File "/cpfs01/user/chenqin.p/anaconda3/envs/moe/lib/python3.10/http/client.py", line 318, in begin
    version, status, reason = self._read_status()
  File "/cpfs01/user/chenqin.p/anaconda3/envs/moe/lib/python3.10/http/client.py", line 287, in _read_status
    raise RemoteDisconnected("Remote end closed connection without"
http.client.RemoteDisconnected: Remote end closed connection without response

During handling of the above exception, another exception occurred:

Traceback (most recent call last):
  File "/cpfs01/user/chenqin.p/anaconda3/envs/moe/lib/python3.10/site-packages/requests/adapters.py", line 486, in send
    resp = conn.urlopen(
  File "/cpfs01/user/chenqin.p/anaconda3/envs/moe/lib/python3.10/site-packages/urllib3/connectionpool.py", line 799, in urlopen
    retries = retries.increment(
  File "/cpfs01/user/chenqin.p/anaconda3/envs/moe/lib/python3.10/site-packages/urllib3/util/retry.py", line 592, in increment
    raise MaxRetryError(_pool, url, error or ResponseError(cause))
urllib3.exceptions.MaxRetryError: HTTPSConnectionPool(host='api.wandb.ai', port=443): Max retries exceeded with url: /graphql (Caused by ProxyError('Cannot connect to proxy.', RemoteDisconnected('Remote end closed connection without response')))

During handling of the above exception, another exception occurred:

Traceback (most recent call last):
  File "/cpfs01/user/chenqin.p/anaconda3/envs/moe/lib/python3.10/site-packages/wandb/sdk/lib/retry.py", line 131, in __call__
    result = self._call_fn(*args, **kwargs)
  File "/cpfs01/user/chenqin.p/anaconda3/envs/moe/lib/python3.10/site-packages/wandb/sdk/internal/internal_api.py", line 369, in execute
    return self.client.execute(*args, **kwargs)  # type: ignore
  File "/cpfs01/user/chenqin.p/anaconda3/envs/moe/lib/python3.10/site-packages/wandb/vendor/gql-0.2.0/wandb_gql/client.py", line 52, in execute
    result = self._get_result(document, *args, **kwargs)
  File "/cpfs01/user/chenqin.p/anaconda3/envs/moe/lib/python3.10/site-packages/wandb/vendor/gql-0.2.0/wandb_gql/client.py", line 60, in _get_result
    return self.transport.execute(document, *args, **kwargs)
  File "/cpfs01/user/chenqin.p/anaconda3/envs/moe/lib/python3.10/site-packages/wandb/sdk/lib/gql_request.py", line 58, in execute
    request = self.session.post(self.url, **post_args)
  File "/cpfs01/user/chenqin.p/anaconda3/envs/moe/lib/python3.10/site-packages/requests/sessions.py", line 637, in post
    return self.request("POST", url, data=data, json=json, **kwargs)
  File "/cpfs01/user/chenqin.p/anaconda3/envs/moe/lib/python3.10/site-packages/requests/sessions.py", line 589, in request
    resp = self.send(prep, **send_kwargs)
  File "/cpfs01/user/chenqin.p/anaconda3/envs/moe/lib/python3.10/site-packages/requests/sessions.py", line 703, in send
    r = adapter.send(request, **kwargs)
  File "/cpfs01/user/chenqin.p/anaconda3/envs/moe/lib/python3.10/site-packages/requests/adapters.py", line 513, in send
    raise ProxyError(e, request=request)
requests.exceptions.ProxyError: HTTPSConnectionPool(host='api.wandb.ai', port=443): Max retries exceeded with url: /graphql (Caused by ProxyError('Cannot connect to proxy.', RemoteDisconnected('Remote end closed connection without response')))
2024-03-31 12:56:41,573 DEBUG   HandlerThread:3789203 [handler.py:handle_request():146] handle_request: keepalive
2024-03-31 12:56:46,574 DEBUG   HandlerThread:3789203 [handler.py:handle_request():146] handle_request: keepalive
2024-03-31 12:56:51,575 DEBUG   HandlerThread:3789203 [handler.py:handle_request():146] handle_request: keepalive
2024-03-31 12:56:56,576 DEBUG   HandlerThread:3789203 [handler.py:handle_request():146] handle_request: keepalive
2024-03-31 12:57:01,577 DEBUG   HandlerThread:3789203 [handler.py:handle_request():146] handle_request: keepalive
2024-03-31 12:57:06,578 DEBUG   HandlerThread:3789203 [handler.py:handle_request():146] handle_request: keepalive
2024-03-31 12:57:11,579 DEBUG   HandlerThread:3789203 [handler.py:handle_request():146] handle_request: keepalive
2024-03-31 12:57:16,580 DEBUG   HandlerThread:3789203 [handler.py:handle_request():146] handle_request: cancel
2024-03-31 12:57:16,580 DEBUG   HandlerThread:3789203 [handler.py:handle_request():146] handle_request: cancel
2024-03-31 12:57:18,586 DEBUG   HandlerThread:3789203 [handler.py:handle_request():146] handle_request: shutdown
2024-03-31 12:57:18,586 INFO    HandlerThread:3789203 [handler.py:finish():869] shutting down handler
2024-03-31 12:57:19,580 INFO    WriterThread:3789203 [datastore.py:close():296] close: /cpfs01/user/chenqin.p/dyh/MOELoRA-peft/wandb/run-20240331_125546-1viczsce/run-1viczsce.wandb
2024-03-31 12:57:29,265 DEBUG   SenderThread:3789203 [sender.py:send():391] Record cancelled: run
2024-03-31 12:57:29,266 INFO    SenderThread:3789203 [sender.py:finish():1572] shutting down sender
